Workbook

Sheet Lisez-moi
A1: Solia · Grille de lead scoring
A2: Base du cahier des charges CRM · version du 12/10/2026 (C6 et C18 retirés, poids alignés sur le document) · points de départ à recalibrer après 3 mois ou 30 réservations
A4: Deux scores sur 100 | B4: Score de conversion (Contact à Réservé) = profil (30 max) + comportement (70 max) + points négatifs. Score d'engagement (Réservé à Abonné) = points obtenus ÷ points atteignables à date × 100.
A5: Règle de preuve | B5: Pas de preuve, pas de points. Chaque critère a une source vérifiable dans le CRM (colonne « Preuve »). On score les clics, jamais les ouvertures d'e-mail.
A6: Grille identique | B6: Les mêmes points pour les trois cibles. La cible sert à attribuer la référente et au contrôle d'équité (onglet Pilotage du document).
A7: Indicateur seul | B7: Les scores aident à prioriser. Ils ne déclenchent aucune action automatique et ne décident rien seuls.
A8: Onglets | B8: Grille conversion · Grille engagement · Négatifs et paliers · Simulateur conversion · Simulateur engagement · Champs CRM.
A9: Comment modifier | B9: Changer un poids dans la colonne « Points » des grilles (bleu) : les simulateurs se recalculent. Dans les simulateurs, ne saisir que les cellules jaunes.
A10: Exemples préremplis | B10: Simulateur conversion : Monique, senior, jour 8 (attendu 77, Prêt à réserver). Simulateur engagement : Monique après son voyage, abonnée et active (attendu 81, Fidèle).
A11: Points négatifs | B11: Ils s'appliquent après les plafonds du score de conversion, et avant le prorata du score d'engagement.
A13: Légende
A14: Saisie | B14: Cellule à remplir (simulateurs)
A15: 10 | B15: Poids modifiable (grilles), en bleu
A16: Calcul | B16: Formule, ne pas écraser

Sheet Grille conversion
A1: Score de conversion · Contact à Réservé
A2: Profil plafonné à 30 · comportement plafonné à 70 · engagement digital (C4 à C8) plafonné à 12 · un seul critère d'origine
A4: Code | B4: Bloc | C4: Critère | D4: Points | E4: Plafond (fois) | F4: Points max | G4: Dégressif | H4: Process | I4: Preuve dans le CRM | J4: Saisie
A5: P1 | B5: Profil | C5: Cible identifiée (senior, parent solo, célibataire) | D5: 5 | E5: 1 | F5: =D5*E5 -> 5 | G5: Non | H5: 01, 03 | I5: Champ cible, confirmé à la découverte | J5: Manuelle
A6: P2 | B6: Profil | C6: Coordonnée vérifiée | D6: 3 | E6: 1 | F6: =D6*E6 -> 3 | G6: Non | H6: 01, 02 | I6: E-mail délivré sans rebond ou appel abouti | J6: Automatique
A7: P3 | B7: Profil | C7: Consentement newsletter | D7: 2 | E7: 1 | F7: =D7*E7 -> 2 | G7: Non | H7: 01 | I7: Journal des consentements horodaté | J7: Automatique
A8: P4 | B8: Profil | C8: Consentement WhatsApp | D8: 3 | E8: 1 | F8: =D8*E8 -> 3 | G8: Non | H8: 01 | I8: Journal des consentements horodaté | J8: Automatique
A9: P5 | B9: Profil | C9: Envie de voyage qui correspond à un départ du planning | D9: 5 | E9: 1 | F9: =D9*E9 -> 5 | G9: Non | H9: 01, 02 | I9: Champ envie relié à un départ du planning | J9: Manuelle
A10: P6 | B10: Profil | C10: Dates compatibles avec un départ ouvert (places restantes) | D10: 6 | E10: 1 | F10: =D10*E10 -> 6 | G10: Non | H10: 03 | I10: Contraintes de dates comparées au planning ; confirmées à l'oral ou par écrit | J10: Manuelle + planning
A11: P7 | B11: Profil | C11: Budget compatible avec le prix du départ visé | D11: 6 | E11: 1 | F11: =D11*E11 -> 6 | G11: Non | H11: 03 | I11: Budget saisi en découverte | J11: Manuelle
A12: C1 | B12: Origine | C12: Recommandé par un parrain | D12: 11 | E12: 1 | F12: =D12*E12 -> 11 | G12: Non | H12: 15, 01 | I12: Code parrain saisi | J12: Manuelle
A13: C2 | B13: Origine | C13: Rencontre en personne (stand, agence, partenaire) | D13: 4 | E13: 1 | F13: =D13*E13 -> 4 | G13: Non | H13: 01 | I13: Origine saisie le jour même | J13: Manuelle
A14: C3 | B14: Origine | C14: QR code ou formulaire du site | D14: 3 | E14: 1 | F14: =D14*E14 -> 3 | G14: Non | H14: 01 | I14: Formulaire horodaté | J14: Automatique
A15: C4 | B15: Digital | C15: Clic dans le message de bienvenue vers les offres | D15: 4 | E15: 1 | F15: =D15*E15 -> 4 | G15: Oui | H15: 01 | I15: Lien tracké propre à la fiche | J15: Automatique
A16: C5 | B16: Digital | C16: Clic dans la newsletter vers une offre | D16: 3 | E16: 3 | F16: =D16*E16 -> 9 | G16: Oui | H16: 01, 14 | I16: Lien tracké propre à la fiche | J16: Automatique
... A29: C20 | B29: Achat | C29: Demande de liste d'attente sur un départ complet | D29: 6 | E29: 1 | F29: =D29*E29 -> 6 | G29: Oui | H29: 04 | I29: Liste d'attente du départ | J29: Manuelle
C31: Profil (max théorique, plafond 30) | F31: =SUMIFS(F5:F29,B5:B29,"Profil") -> 30
C32: Origine (seul le plus fort compte) | F32: =MAX(D12:D14) -> 11
C33: Digital (plafond 12) | F33: =MIN(12,SUMIFS(F5:F29,B5:B29,"Digital")) -> 12
C34: Demande, découverte, achat (théorique) | F34: =SUMIFS(F5:F29,B5:B29,"Demande")+SUMIFS(F5:F29,B5:B29,"Découverte")+SUMIFS(F5:F29,B5:B29,"Achat") -> 99
C35: Comportement retenu (plafond 70) | F35: =MIN(70,F32+F33+F34) -> 70
C36: Contrôle : le profil doit valoir 30

Sheet Grille engagement
A1: Score d'engagement · Réservé à Abonné
A2: Avant 20 · pendant 20 · après 25 · fidélité 35 (plafond) · calcul au prorata des points atteignables à date
A4: Code | B4: Bloc | C4: Critère | D4: Points | E4: Règle | F4: Process | G4: Preuve dans le CRM | H4: Glissant
A5: E1 | B5: Avant | C5: Appel de bienvenue abouti sous 48 h | D5: 4 | E5: Oui = 4 | F5: 05 | G5: Date de l'appel de bienvenue | H5: Non
A6: E2 | B6: Avant | C6: Message posté dans le groupe WhatsApp du voyage | D6: 4 | E6: Oui = 4 | F6: 06 | G6: Case cochée par la référente | H6: Non
A7: E3 | B7: Avant | C7: Solde réglé à l'échéance (J-60) | D7: 4 | E7: Oui = 4 | F7: 06 | G7: Date et montant du solde | H7: Non
A8: E4 | B8: Avant | C8: Présent au Soli'apéro brise-glace | D8: 8 | E8: Oui = 8 | F8: 07 | G8: Présence cochée | H8: Non
A9: E5 | B9: Pendant | C9: Satisfaction à chaud | D9: 12 | E9: 9 ou 10 = 12 ; 7 ou 8 = 6 ; 6 ou moins = 0 | F9: 08 | G9: Note saisie par l'animatrice | H9: Non
A10: E6 | B10: Pendant | C10: Aucun incident resté sans solution en fin de séjour | D10: 4 | E10: Oui = 4 | F10: 08, 16 | G10: Fiche incident résolue | H10: Non
A11: E7 | B11: Pendant | C11: Photos ou messages partagés dans le groupe | D11: 4 | E11: Oui = 4 | F11: 08 | G11: Case cochée par l'animatrice | H11: Non
A12: E8 | B12: Après | C12: Présent au Soli'apéro retour | D12: 8 | E12: Oui = 8 | F12: 10 | G12: Présence cochée | H12: Non
A13: E9 | B13: Après | C13: Note de recommandation (NPS) | D13: 10 | E13: 9 ou 10 = 10 ; 7 ou 8 = 5 ; 6 ou moins = 0 | F13: 12 | G13: Réponse à l'enquête | H13: Non
A14: E10 | B14: Après | C14: Avis Google publié | D14: 7 | E14: Oui = 7 | F14: 12, 17 | G14: Vérifié par Florentine | H14: Non
A15: E11 | B15: Fidélité | C15: Abonnement souscrit et actif | D15: 10 | E15: Oui = 10 | F15: 11, 13 | G15: Statut Abonné | H15: Oui
A16: E12 | B16: Fidélité | C16: Activité ou événement fréquenté dans les 30 derniers jours | D16: 10 | E16: Oui = 10 | F16: 13, 14 | G16: Participation cochée | H16: Oui
... A19: E15 | B19: Fidélité | C19: Nouveau voyage réservé dans les 12 mois | D19: 10 | E19: Oui = 10 | F19: 15 | G19: Statut Réservé | H19: Oui
C21: Avant (plafond 20) | D21: =MIN(20,SUMIFS(D5:D19,B5:B19,"Avant")) -> 20
C22: Pendant (plafond 20) | D22: =MIN(20,SUMIFS(D5:D19,B5:B19,"Pendant")) -> 20
C23: Après (plafond 25) | D23: =MIN(25,SUMIFS(D5:D19,B5:B19,"Après")) -> 25
C24: Fidélité (plafond 35) | D24: =MIN(35,SUMIFS(D5:D19,B5:B19,"Fidélité")+D18) -> 35 | E24: E14 compté deux fois (2 filleuls)
C25: Total (doit valoir 100) | D25: =SUM(D21:D24) -> 100

Sheet Négatifs et paliers
A1: Points négatifs, dégressivité et paliers
A2: Le score final reste entre 0 et 100
A4: Code | B4: Score | C4: Événement | D4: Points | E4: Process | F4: Levée
A5: N1 | B5: Conversion | C5: Désinscription de la newsletter | D5: -5 | E5: 01 | F5: Réinscription
A6: N2 | B6: Conversion | C6: Retrait du consentement WhatsApp | D6: -3 | E6: 01 | F6: Nouveau consentement
A7: N3 | B7: Conversion | C7: Coordonnée invalide (rebond, numéro non attribué) ; P2 retiré | D7: -5 | E7: 01 | F7: Coordonnée corrigée
A8: N4 | B8: Conversion | C8: Rendez-vous découverte non honoré sans prévenir | D8: -8 | E8: 03 | F8: Rendez-vous réalisé
A9: N5 | B9: Conversion | C9: Devis arrivé à expiration sans réponse (J+30) | D9: -10 | E9: 04 | F9: Nouvelle demande
A10: N6 | B10: Conversion | C10: Refus explicite (« pas pour le moment ») | D10: -15 | E10: 02, 04 | F10: Nouvelle demande
A11: M1 | B11: Engagement | C11: Réclamation ouverte | D11: -10 | E11: 16 | F11: Résolution confirmée à J+7
A12: M2 | B12: Engagement | C12: Avis public de 3 étoiles ou moins | D12: -10 | E12: 17 | F12: Résolution (process 16)
A13: M3 | B13: Engagement | C13: Mise en demeure pour le solde (J-57) | D13: -8 | E13: 06 | F13: Solde encaissé
A14: M4 | B14: Engagement | C14: Abonné sans activité depuis 60 jours | D14: -10 | E14: 13 | F14: Nouvelle participation
A15: M5 | B15: Engagement | C15: Désinscription de la newsletter | D15: -5 | E15: 14 | F15: Réinscription
A17: Clôture du score (pas de points) : passage en Perdu (comportement remis à 0, profil conservé), annulation, résiliation (score figé, motif obligatoire).
A19: Dégressivité du comportement (C4 à C20)
A20: Dès (jours) | B20: Jusqu'à | C20: Coefficient
A21: 0 | B21: 30 | C21: 1
A22: 31 | B22: 60 | C22: 0.5
A23: 61 | B23: 90 | C23: 0.25
A24: 91 | B24: au-delà | C24: 0
A25: Origine (C1 à C3) et profil : pas de dégressivité. P6 tombe à 0 quand le départ visé est complet ou passé.
A27: Paliers de lecture
A28: Dès | B28: Conversion | D28: Dès | E28: Engagement
A29: 0 | B29: Froid | D29: 0 | E29: Distant
A30: 25 | B30: Tiède | D30: 40 | E30: Engagé
A31: 50 | B31: Chaud | D31: 65 | E31: Fidèle
A32: 75 | B32: Prêt à réserver | D32: 85 | E32: Ambassadeur

Sheet Simulateur conversion
A1: Simulateur · score de conversion
A2: Exemple prérempli : Monique, senior, jour 8. Saisir uniquement les cellules jaunes.
A4: Code | B4: Critère | C4: Points | D4: Plafond | E4: Nb d'occurrences | F4: Âge (jours) | G4: Coefficient | H4: Points obtenus
A5: P1 | B5: ='Grille conversion'!C5 -> Cible identifiée (senior, parent solo, célibataire) | C5: ='Grille conversion'!D5 -> 5 | D5: ='Grille conversion'!E5 -> 1 | E5: 1 | G5: 1 | H5: =MIN(E5,D5)*C5*G5 -> 5
A6: P2 | B6: ='Grille conversion'!C6 -> Coordonnée vérifiée | C6: ='Grille conversion'!D6 -> 3 | D6: ='Grille conversion'!E6 -> 1 | E6: 1 | G6: 1 | H6: =MIN(E6,D6)*C6*G6 -> 3
A7: P3 | B7: ='Grille conversion'!C7 -> Consentement newsletter | C7: ='Grille conversion'!D7 -> 2 | D7: ='Grille conversion'!E7 -> 1 | E7: 0 | G7: 1 | H7: =MIN(E7,D7)*C7*G7 -> 0
A8: P4 | B8: ='Grille conversion'!C8 -> Consentement WhatsApp | C8: ='Grille conversion'!D8 -> 3 | D8: ='Grille conversion'!E8 -> 1 | E8: 0 | G8: 1 | H8: =MIN(E8,D8)*C8*G8 -> 0
A9: P5 | B9: ='Grille conversion'!C9 -> Envie de voyage qui correspond à un départ du planning | C9: ='Grille conversion'!D9 -> 5 | D9: ='Grille conversion'!E9 -> 1 | E9: 1 | G9: 1 | H9: =MIN(E9,D9)*C9*G9 -> 5
A10: P6 | B10: ='Grille conversion'!C10 -> Dates compatibles avec un départ ouvert (places restantes) | C10: ='Grille conversion'!D10 -> 6 | D10: ='Grille conversion'!E10 -> 1 | E10: 1 | G10: 1 | H10: =MIN(E10,D10)*C10*G10 -> 6
A11: P7 | B11: ='Grille conversion'!C11 -> Budget compatible avec le prix du départ visé | C11: ='Grille conversion'!D11 -> 6 | D11: ='Grille conversion'!E11 -> 1 | E11: 1 | G11: 1 | H11: =MIN(E11,D11)*C11*G11 -> 6
A12: C1 | B12: ='Grille conversion'!C12 -> Recommandé par un parrain | C12: ='Grille conversion'!D12 -> 11 | D12: ='Grille conversion'!E12 -> 1 | E12: 0 | G12: 1 | H12: =MIN(E12,D12)*C12*G12 -> 0
A13: C2 | B13: ='Grille conversion'!C13 -> Rencontre en personne (stand, agence, partenaire) | C13: ='Grille conversion'!D13 -> 4 | D13: ='Grille conversion'!E13 -> 1 | E13: 0 | G13: 1 | H13: =MIN(E13,D13)*C13*G13 -> 0
A14: C3 | B14: ='Grille conversion'!C14 -> QR code ou formulaire du site | C14: ='Grille conversion'!D14 -> 3 | D14: ='Grille conversion'!E14 -> 1 | E14: 0 | G14: 1 | H14: =MIN(E14,D14)*C14*G14 -> 0
A15: C4 | B15: ='Grille conversion'!C15 -> Clic dans le message de bienvenue vers les offres | C15: ='Grille conversion'!D15 -> 4 | D15: ='Grille conversion'!E15 -> 1 | E15: 0 | F15: 0 | G15: =LOOKUP(F15,'Négatifs et paliers'!$A$21:$A$24,'Négatifs et paliers'!$C$21:$C$24) -> 1 | H15: =MIN(E15,D15)*C15*G15 -> 0
A16: C5 | B16: ='Grille conversion'!C16 -> Clic dans la newsletter vers une offre | C16: ='Grille conversion'!D16 -> 3 | D16: ='Grille conversion'!E16 -> 3 | E16: 0 | F16: 0 | G16: =LOOKUP(F16,'Négatifs et paliers'!$A$21:$A$24,'Négatifs et paliers'!$C$21:$C$24) -> 1 | H16: =MIN(E16,D16)*C16*G16 -> 0
A17: C7 | B17: ='Grille conversion'!C17 -> Commentaire ou DM sans question précise | C17: ='Grille conversion'!D17 -> 3 | D17: ='Grille conversion'!E17 -> 2 | E17: 0 | F17: 0 | G17: =LOOKUP(F17,'Négatifs et paliers'!$A$21:$A$24,'Négatifs et paliers'!$C$21:$C$24) -> 1 | H17: =MIN(E17,D17)*C17*G17 -> 0
A18: C8 | B18: ='Grille conversion'!C18 -> Programme téléchargé via formulaire | C18: ='Grille conversion'!D18 -> 4 | D18: ='Grille conversion'!E18 -> 1 | E18: 0 | F18: 0 | G18: =LOOKUP(F18,'Négatifs et paliers'!$A$21:$A$24,'Négatifs et paliers'!$C$21:$C$24) -> 1 | H18: =MIN(E18,D18)*C18*G18 -> 0
A19: C9 | B19: ='Grille conversion'!C19 -> Demande écrite avec une question sur un voyage | C19: ='Grille conversion'!D19 -> 10 | D19: ='Grille conversion'!E19 -> 1 | E19: 0 | F19: 0 | G19: =LOOKUP(F19,'Négatifs et paliers'!$A$21:$A$24,'Négatifs et paliers'!$C$21:$C$24) -> 1 | H19: =MIN(E19,D19)*C19*G19 -> 0
A20: C10 | B20: ='Grille conversion'!C20 -> Appel entrant à l'agence | C20: ='Grille conversion'!D20 -> 15 | D20: ='Grille conversion'!E20 -> 1 | E20: 1 | F20: 8 | G20: =LOOKUP(F20,'Négatifs et paliers'!$A$21:$A$24,'Négatifs et paliers'!$C$21:$C$24) -> 1 | H20: =MIN(E20,D20)*C20*G20 -> 15
A21: C11 | B21: ='Grille conversion'!C21 -> Visite spontanée à l'agence | C21: ='Grille conversion'!D21 -> 15 | D21: ='Grille conversion'!E21 -> 1 | E21: 0 | F21: 0 | G21: =LOOKUP(F21,'Négatifs et paliers'!$A$21:$A$24,'Négatifs et paliers'!$C$21:$C$24) -> 1 | H21: =MIN(E21,D21)*C21*G21 -> 0
A22: C12 | B22: ='Grille conversion'!C22 -> Réponse à une relance (J+3, J+7) | C22: ='Grille conversion'!D22 -> 4 | D22: ='Grille conversion'!E22 -> 2 | E22: 0 | F22: 0 | G22: =LOOKUP(F22,'Négatifs et paliers'!$A$21:$A$24,'Négatifs et paliers'!$C$21:$C$24) -> 1 | H22: =MIN(E22,D22)*C22*G22 -> 0
A23: C13 | B23: ='Grille conversion'!C23 -> Rendez-vous découverte accepté | C23: ='Grille conversion'!D23 -> 6 | D23: ='Grille conversion'!E23 -> 1 | E23: 1 | F23: 3 | G23: =LOOKUP(F23,'Négatifs et paliers'!$A$21:$A$24,'Négatifs et paliers'!$C$21:$C$24) -> 1 | H23: =MIN(E23,D23)*C23*G23 -> 6
A24: C14 | B24: ='Grille conversion'!C24 -> Rendez-vous découverte réalisé | C24: ='Grille conversion'!D24 -> 12 | D24: ='Grille conversion'!E24 -> 1 | E24: 1 | F24: 3 | G24: =LOOKUP(F24,'Négatifs et paliers'!$A$21:$A$24,'Négatifs et paliers'!$C$21:$C$24) -> 1 | H24: =MIN(E24,D24)*C24*G24 -> 12
A25: C15 | B25: ='Grille conversion'!C25 -> Accord pour recevoir un devis | C25: ='Grille conversion'!D25 -> 8 | D25: ='Grille conversion'!E25 -> 1 | E25: 1 | F25: 3 | G25: =LOOKUP(F25,'Négatifs et paliers'!$A$21:$A$24,'Négatifs et paliers'!$C$21:$C$24) -> 1 | H25: =MIN(E25,D25)*C25*G25 -> 8
A26: C16 | B26: ='Grille conversion'!C26 -> Appel de relance J+3 abouti | C26: ='Grille conversion'!D26 -> 5 | D26: ='Grille conversion'!E26 -> 1 | E26: 1 | F26: 0 | G26: =LOOKUP(F26,'Négatifs et paliers'!$A$21:$A$24,'Négatifs et paliers'!$C$21:$C$24) -> 1 | H26: =MIN(E26,D26)*C26*G26 -> 5
... A29: C20 | B29: ='Grille conversion'!C29 -> Demande de liste d'attente sur un départ complet | C29: ='Grille conversion'!D29 -> 6 | D29: ='Grille conversion'!E29 -> 1 | E29: 0 | F29: 0 | G29: =LOOKUP(F29,'Négatifs et paliers'!$A$21:$A$24,'Négatifs et paliers'!$C$21:$C$24) -> 1 | H29: =MIN(E29,D29)*C29*G29 -> 0
A31: Négatifs
A32: N1 | B32: ='Négatifs et paliers'!C5 -> Désinscription de la newsletter | C32: ='Négatifs et paliers'!D5 -> -5 | D32: 1 | E32: 0 | H32: =MIN(E32,D32)*C32 -> 0
A33: N2 | B33: ='Négatifs et paliers'!C6 -> Retrait du consentement WhatsApp | C33: ='Négatifs et paliers'!D6 -> -3 | D33: 1 | E33: 0 | H33: =MIN(E33,D33)*C33 -> 0
A34: N3 | B34: ='Négatifs et paliers'!C7 -> Coordonnée invalide (rebond, numéro non attribué) ; P2 retiré | C34: ='Négatifs et paliers'!D7 -> -5 | D34: 1 | E34: 0 | H34: =MIN(E34,D34)*C34 -> 0
A35: N4 | B35: ='Négatifs et paliers'!C8 -> Rendez-vous découverte non honoré sans prévenir | C35: ='Négatifs et paliers'!D8 -> -8 | D35: 1 | E35: 0 | H35: =MIN(E35,D35)*C35 -> 0
A36: N5 | B36: ='Négatifs et paliers'!C9 -> Devis arrivé à expiration sans réponse (J+30) | C36: ='Négatifs et paliers'!D9 -> -10 | D36: 1 | E36: 0 | H36: =MIN(E36,D36)*C36 -> 0
A37: N6 | B37: ='Négatifs et paliers'!C10 -> Refus explicite (« pas pour le moment ») | C37: ='Négatifs et paliers'!D10 -> -15 | D37: 1 | E37: 0 | H37: =MIN(E37,D37)*C37 -> 0
F39: Profil (plafond 30) | H39: =MIN(30,SUM(H5:H11)) -> 25
F40: Origine (le plus fort) | H40: =MAX(H12:H14) -> 0
F41: Digital (plafond 12) | H41: =MIN(12,SUM(H15:H18)) -> 0
F42: Demande, découverte, achat | H42: =SUM(H19:H29) -> 52
F43: Comportement (plafond 70) | H43: =MIN(70,H40+H41+H42) -> 52
F44: Points négatifs | H44: =SUM(H32:H37) -> 0
F45: SCORE DE CONVERSION /100 | H45: =ROUND(MAX(0,MIN(100,H39+H43+H44)),0) -> 77
...

Sheet Simulateur engagement
A1: Simulateur · score d'engagement
A2: Exemple prérempli : Monique après son voyage, abonnée et active. Atteignable = 1 si l'étape est passée (lu dans le planning).
A4: Code | B4: Bloc | C4: Critère | D4: Points max | E4: Atteignable (1/0) | F4: Saisie | G4: Points atteignables | H4: Points obtenus
A5: E1 | B5: Avant | C5: ='Grille engagement'!C5 -> Appel de bienvenue abouti sous 48 h | D5: ='Grille engagement'!D5 -> 4 | E5: 1 | F5: 1 | G5: =D5*E5 -> 4 | H5: =E5*MIN(F5,1)*D5 -> 4
A6: E2 | B6: Avant | C6: ='Grille engagement'!C6 -> Message posté dans le groupe WhatsApp du voyage | D6: ='Grille engagement'!D6 -> 4 | E6: 1 | F6: 0 | G6: =D6*E6 -> 4 | H6: =E6*MIN(F6,1)*D6 -> 0
A7: E3 | B7: Avant | C7: ='Grille engagement'!C7 -> Solde réglé à l'échéance (J-60) | D7: ='Grille engagement'!D7 -> 4 | E7: 1 | F7: 1 | G7: =D7*E7 -> 4 | H7: =E7*MIN(F7,1)*D7 -> 4
A8: E4 | B8: Avant | C8: ='Grille engagement'!C8 -> Présent au Soli'apéro brise-glace | D8: ='Grille engagement'!D8 -> 8 | E8: 1 | F8: 1 | G8: =D8*E8 -> 8 | H8: =E8*MIN(F8,1)*D8 -> 8
A9: E5 | B9: Pendant | C9: ='Grille engagement'!C9 -> Satisfaction à chaud | D9: ='Grille engagement'!D9 -> 12 | E9: 1 | F9: 9 | G9: =D9*E9 -> 12 | H9: =E9*IF(F9>=9,D9,IF(F9>=7,D9/2,0)) -> 12
A10: E6 | B10: Pendant | C10: ='Grille engagement'!C10 -> Aucun incident resté sans solution en fin de séjour | D10: ='Grille engagement'!D10 -> 4 | E10: 1 | F10: 1 | G10: =D10*E10 -> 4 | H10: =E10*MIN(F10,1)*D10 -> 4
A11: E7 | B11: Pendant | C11: ='Grille engagement'!C11 -> Photos ou messages partagés dans le groupe | D11: ='Grille engagement'!D11 -> 4 | E11: 1 | F11: 1 | G11: =D11*E11 -> 4 | H11: =E11*MIN(F11,1)*D11 -> 4
A12: E8 | B12: Après | C12: ='Grille engagement'!C12 -> Présent au Soli'apéro retour | D12: ='Grille engagement'!D12 -> 8 | E12: 1 | F12: 1 | G12: =D12*E12 -> 8 | H12: =E12*MIN(F12,1)*D12 -> 8
A13: E9 | B13: Après | C13: ='Grille engagement'!C13 -> Note de recommandation (NPS) | D13: ='Grille engagement'!D13 -> 10 | E13: 1 | F13: 10 | G13: =D13*E13 -> 10 | H13: =E13*IF(F13>=9,D13,IF(F13>=7,D13/2,0)) -> 10
A14: E10 | B14: Après | C14: ='Grille engagement'!C14 -> Avis Google publié | D14: ='Grille engagement'!D14 -> 7 | E14: 1 | F14: 1 | G14: =D14*E14 -> 7 | H14: =E14*MIN(F14,1)*D14 -> 7
A15: E11 | B15: Fidélité | C15: ='Grille engagement'!C15 -> Abonnement souscrit et actif | D15: ='Grille engagement'!D15 -> 10 | E15: 1 | F15: 1 | G15: =D15*E15 -> 10 | H15: =E15*MIN(F15,1)*D15 -> 10
A16: E12 | B16: Fidélité | C16: ='Grille engagement'!C16 -> Activité ou événement fréquenté dans les 30 derniers jours | D16: ='Grille engagement'!D16 -> 10 | E16: 1 | F16: 1 | G16: =D16*E16 -> 10 | H16: =E16*MIN(F16,1)*D16 -> 10
A17: E13 | B17: Fidélité | C17: ='Grille engagement'!C17 -> Au moins 3 participations sur 90 jours | D17: ='Grille engagement'!D17 -> 5 | E17: 1 | F17: 0 | G17: =D17*E17 -> 5 | H17: =E17*MIN(F17,1)*D17 -> 0
A18: E14 | B18: Fidélité | C18: ='Grille engagement'!C18 -> Filleul dont l'acompte est encaissé | D18: ='Grille engagement'!D18*2 -> 10 | E18: 1 | F18: 0 | G18: =D18*E18 -> 10 | H18: =E18*MIN(F18,2)*'Grille engagement'!D18 -> 0
A19: E15 | B19: Fidélité | C19: ='Grille engagement'!C19 -> Nouveau voyage réservé dans les 12 mois | D19: ='Grille engagement'!D19 -> 10 | E19: 1 | F19: 0 | G19: =D19*E19 -> 10 | H19: =E19*MIN(F19,1)*D19 -> 0
C21: Saisie : 1 ou 0, sauf E5 et E9 (note sur 10) et E14 (nombre de filleuls)
A22: Négatifs
A23: M1 | C23: ='Négatifs et paliers'!C11 -> Réclamation ouverte | D23: ='Négatifs et paliers'!D11 -> -10 | F23: 0 | H23: =MIN(F23,1)*D23 -> 0
A24: M2 | C24: ='Négatifs et paliers'!C12 -> Avis public de 3 étoiles ou moins | D24: ='Négatifs et paliers'!D12 -> -10 | F24: 0 | H24: =MIN(F24,1)*D24 -> 0
A25: M3 | C25: ='Négatifs et paliers'!C13 -> Mise en demeure pour le solde (J-57) | D25: ='Négatifs et paliers'!D13 -> -8 | F25: 0 | H25: =MIN(F25,1)*D25 -> 0
A26: M4 | C26: ='Négatifs et paliers'!C14 -> Abonné sans activité depuis 60 jours | D26: ='Négatifs et paliers'!D14 -> -10 | F26: 0 | H26: =MIN(F26,1)*D26 -> 0
A27: M5 | C27: ='Négatifs et paliers'!C15 -> Désinscription de la newsletter | D27: ='Négatifs et paliers'!D15 -> -5 | F27: 0 | H27: =MIN(F27,1)*D27 -> 0
C29: Avant (plafond 20) | G29: =MIN(20,SUMIFS(G5:G19,B5:B19,"Avant")) -> 20 | H29: =MIN(20,SUMIFS(H5:H19,B5:B19,"Avant")) -> 16
C30: Pendant (plafond 20) | G30: =MIN(20,SUMIFS(G5:G19,B5:B19,"Pendant")) -> 20 | H30: =MIN(20,SUMIFS(H5:H19,B5:B19,"Pendant")) -> 20
C31: Après (plafond 25) | G31: =MIN(25,SUMIFS(G5:G19,B5:B19,"Après")) -> 25 | H31: =MIN(25,SUMIFS(H5:H19,B5:B19,"Après")) -> 25
C32: Fidélité (plafond 35) | G32: =MIN(35,SUMIFS(G5:G19,B5:B19,"Fidélité")) -> 35 | H32: =MIN(35,SUMIFS(H5:H19,B5:B19,"Fidélité")) -> 20
C33: Total | G33: =SUM(G29:G32) -> 100 | H33: =SUM(H29:H32) -> 81
C34: Points négatifs | H34: =SUM(H23:H27) -> 0
C35: SCORE D'ENGAGEMENT /100 | H35: =IF(G33=0,0,ROUND(MAX(0,MIN(100,(H33+H34)/G33*100)),0)) -> 81
C36: Palier | H36: =LOOKUP(H35,'Négatifs et paliers'!$D$29:$D$32,'Négatifs et paliers'!$E$29:$E$32) -> Fidèle

Sheet Champs CRM
A1: Champs que le CRM doit enregistrer
A2: Sans ces champs, la règle « pas de preuve, pas de points » ne tient pas
A4: Objet | B4: Champ | C4: Type | D4: Obligatoire | E4: Critères alimentés | F4: Process
A5: Fiche contact | B5: Identité (prénom, nom, téléphone, e-mail) | C5: Texte | D5: Oui | E5: P2, N3 | F5: 01
A6: Fiche contact | B6: Cible | C6: Liste : Senior, Parent solo, Célibataire | D6: Oui | E6: P1 | F6: 01
A7: Fiche contact | B7: Origine du contact | C7: Liste : Stand, Agence, Partenaire, Flyer QR code, Site, Réseau social, Parrainage, Appel entrant | D7: Oui | E7: C1 à C3 | F7: 01
A8: Fiche contact | B8: Code du parrain | C8: Texte, contrôlé | D8: Si parrainage | E8: C1, E14 | F8: 15
A9: Fiche contact | B9: Canal préféré | C9: Liste | D9: Oui | E9: - | F9: 01
A10: Fiche contact | B10: Envie de voyage | C10: Lien vers un départ du planning | D10: Non | E10: P5 | F10: 01, 02
A11: Fiche contact | B11: Contraintes de dates | C11: Période (du, au) | D11: Non | E11: P6 | F11: 03
A12: Fiche contact | B12: Budget déclaré | C12: Montant en € | D12: Non | E12: P7 | F12: 03
A13: Fiche contact | B13: Personnes accompagnantes | C13: Texte ou liens vers fiches | D13: Non | E13: - | F13: 03
A14: Fiche contact | B14: Compte réseau social rattaché | C14: Identifiant | D14: Non | E14: C7 | F14: 17
A15: Fiche contact | B15: Statut | C15: Liste : Contact, Prospect, Devis envoyé, Réservé, Soldé, Voyageur, Abonné, Ancien abonné, Perdu | D15: Oui | E15: Clôtures | F15: 19
... A35: Avis | B35: Plateforme, note, date, réponse, client rattaché | C35: Liste, note, date | D35: Oui | E35: M2, E10 | F35: 17
